<?xml version="1.0" encoding="utf-8"?>
<!-- This URDF was automatically created by SolidWorks to URDF Exporter! Originally created by Stephen Brawner (brawner@gmail.com) 
     Commit Version: 1.6.0-1-g15f4949  Build Version: 1.6.7594.29634
     For more information, please see http://wiki.ros.org/sw_urdf_exporter -->
<robot
  name="four_w_amr">
  <link
    name="base_link">
    <inertial>
      <origin
        xyz="-0.0015714 -3.8096E-05 0.0092412"
        rpy="0 0 0" />
      <mass
        value="0.99262" />
      <inertia
        ixx="0.0049043"
        ixy="-7.0089E-07"
        ixz="-1.9202E-06"
        iyy="0.0069472"
        iyz="1.296E-07"
        izz="0.010883" />
    </inertial>
    <visual>
      <origin
        xyz="0 0 0"
        rpy="0 0 0" />
      <geometry>
        <mesh
          filename="package://four_w_amr/meshes/base_link.STL" />
      </geometry>
      <material
        name="">
        <color
          rgba="1 0.94902 0.89804 1" />
      </material>
    </visual>
    <collision>
      <origin
        xyz="0 0 0"
        rpy="0 0 0" />
      <geometry>
        <mesh
          filename="package://four_w_amr/meshes/base_link.STL" />
      </geometry>
    </collision>
  </link>
  <link
    name="front_right_link">
    <inertial>
      <origin
        xyz="7.98479129751617E-06 1.10220750583739E-05 0.00334456132385286"
        rpy="0 0 0" />
      <mass
        value="0.136050477770583" />
      <inertia
        ixx="0.000149637372346913"
        ixy="-1.49723611912467E-08"
        ixz="-8.99691309444113E-10"
        iyy="0.000149629538452258"
        iyz="2.49639173636771E-10"
        izz="0.000237422132450635" />
    </inertial>
    <visual>
      <origin
        xyz="0 0 0"
        rpy="0 0 0" />
      <geometry>
        <mesh
          filename="package://four_w_amr/meshes/front_right_link.STL" />
      </geometry>
      <material
        name="">
        <color
          rgba="0.792156862745098 0.819607843137255 0.933333333333333 1" />
      </material>
    </visual>
    <collision>
      <origin
        xyz="0 0 0"
        rpy="0 0 0" />
      <geometry>
        <mesh
          filename="package://four_w_amr/meshes/front_right_link.STL" />
      </geometry>
    </collision>
  </link>
  <joint
    name="front_right_joint"
    type="continuous">
    <origin
      xyz="0.09 -0.12514 -0.0092692"
      rpy="1.5708 0 0" />
    <parent
      link="base_link" />
    <child
      link="front_right_link" />
    <axis
      xyz="0 0 1" />
    <limit
      lower="0"
      upper="0"
      effort="0"
      velocity="0" />
  </joint>
  <link
    name="front_left_link">
    <inertial>
      <origin
        xyz="1.1381894112733E-05 7.48568934245096E-06 -0.00334456087259355"
        rpy="0 0 0" />
      <mass
        value="0.13605048957278" />
      <inertia
        ixx="0.000149628181222013"
        ixy="-1.45417054623739E-08"
        ixz="-2.07034268982266E-10"
        iyy="0.000149638739293044"
        iyz="9.04501670155912E-10"
        izz="0.000237422140494481" />
    </inertial>
    <visual>
      <origin
        xyz="0 0 0"
        rpy="0 0 0" />
      <geometry>
        <mesh
          filename="package://four_w_amr/meshes/front_left_link.STL" />
      </geometry>
      <material
        name="">
        <color
          rgba="0.792156862745098 0.819607843137255 0.933333333333333 1" />
      </material>
    </visual>
    <collision>
      <origin
        xyz="0 0 0"
        rpy="0 0 0" />
      <geometry>
        <mesh
          filename="package://four_w_amr/meshes/front_left_link.STL" />
      </geometry>
    </collision>
  </link>
  <joint
    name="front_left_joint"
    type="continuous">
    <origin
      xyz="0.09 0.12514 -0.0092692"
      rpy="1.5708 0 0" />
    <parent
      link="base_link" />
    <child
      link="front_left_link" />
    <axis
      xyz="0 0 -1" />
    <limit
      lower="0"
      upper="0"
      effort="0"
      velocity="0" />
  </joint>
  <link
    name="back_right_link">
    <inertial>
      <origin
        xyz="2.69262244340096E-06 1.34962546564869E-05 0.00334457304464342"
        rpy="0 0 0" />
      <mass
        value="0.136050439819325" />
      <inertia
        ixx="0.000149647306834592"
        ixy="-6.54136891411713E-09"
        ixz="-8.64044775880118E-10"
        iyy="0.000149619394821641"
        iyz="-1.01021792230475E-10"
        izz="0.000237421935786749" />
    </inertial>
    <visual>
      <origin
        xyz="0 0 0"
        rpy="0 0 0" />
      <geometry>
        <mesh
          filename="package://four_w_amr/meshes/back_right_link.STL" />
      </geometry>
      <material
        name="">
        <color
          rgba="0.792156862745098 0.819607843137255 0.933333333333333 1" />
      </material>
    </visual>
    <collision>
      <origin
        xyz="0 0 0"
        rpy="0 0 0" />
      <geometry>
        <mesh
          filename="package://four_w_amr/meshes/back_right_link.STL" />
      </geometry>
    </collision>
  </link>
  <joint
    name="back_right_joint"
    type="continuous">
    <origin
      xyz="-0.09 -0.12514 -0.0092692"
      rpy="1.5708 0 0" />
    <parent
      link="base_link" />
    <child
      link="back_right_link" />
    <axis
      xyz="0 0 1" />
    <limit
      lower="0"
      upper="0"
      effort="0"
      velocity="0" />
  </joint>
  <link
    name="back_left_link">
    <inertial>
      <origin
        xyz="1.13824598607648E-05 7.48507145224148E-06 -0.00334455998739608"
        rpy="0 0 0" />
      <mass
        value="0.13605047153913" />
      <inertia
        ixx="0.00014962817203766"
        ixy="-1.45514561403012E-08"
        ixz="-2.02508595545601E-10"
        iyy="0.000149638713799597"
        iyz="9.01595965330663E-10"
        izz="0.000237422109521262" />
    </inertial>
    <visual>
      <origin
        xyz="0 0 0"
        rpy="0 0 0" />
      <geometry>
        <mesh
          filename="package://four_w_amr/meshes/back_left_link.STL" />
      </geometry>
      <material
        name="">
        <color
          rgba="0.792156862745098 0.819607843137255 0.933333333333333 1" />
      </material>
    </visual>
    <collision>
      <origin
        xyz="0 0 0"
        rpy="0 0 0" />
      <geometry>
        <mesh
          filename="package://four_w_amr/meshes/back_left_link.STL" />
      </geometry>
    </collision>
  </link>
  <joint
    name="back_left_joint"
    type="continuous">
    <origin
      xyz="-0.09 0.12514 -0.0092692"
      rpy="1.5708 0 0" />
    <parent
      link="base_link" />
    <child
      link="back_left_link" />
    <axis
      xyz="0 0 -1" />
    <limit
      lower="0"
      upper="0"
      effort="0"
      velocity="0" />
  </joint>
  <link
    name="top_plate_link">
    <inertial>
      <origin
        xyz="0.000420222783781007 -5.64815892474618E-16 0.051060226584283"
        rpy="0 0 0" />
      <mass
        value="0.0466828966882997" />
      <inertia
        ixx="0.000189247485053159"
        ixy="-1.64633361020445E-19"
        ixz="-5.96136350214113E-08"
        iyy="0.000331558823701719"
        iyz="-7.65829186487116E-20"
        izz="0.000516954502516687" />
    </inertial>
    <visual>
      <origin
        xyz="0 0 0"
        rpy="0 0 0" />
      <geometry>
        <mesh
          filename="package://four_w_amr/meshes/top_plate_link.STL" />
      </geometry>
      <material
        name="">
        <color
          rgba="1 0.937254901960784 0.137254901960784 1" />
      </material>
    </visual>
    <collision>
      <origin
        xyz="0 0 0"
        rpy="0 0 0" />
      <geometry>
        <mesh
          filename="package://four_w_amr/meshes/top_plate_link.STL" />
      </geometry>
    </collision>
  </link>
  <joint
    name="top_plate_joint"
    type="fixed">
    <origin
      xyz="0 0 0"
      rpy="0 0 0" />
    <parent
      link="base_link" />
    <child
      link="top_plate_link" />
    <axis
      xyz="0 0 0" />
  </joint>
  <link
    name="lidar_link">
    <inertial>
      <origin
        xyz="0.0519284763054134 9.19718367893261E-05 0.104952293837966"
        rpy="0 0 0" />
      <mass
        value="1.33010751695787" />
      <inertia
        ixx="0.000613770576870692"
        ixy="-8.01970112250431E-07"
        ixz="-0.000158237807214438"
        iyy="0.000959131136457615"
        iyz="3.09368466835681E-06"
        izz="0.00109694905180103" />
    </inertial>
    <visual>
      <origin
        xyz="0.08 0 -0.1"
        rpy="0 0 3.14" />
      <geometry>
        <mesh
          filename="package://four_w_amr/meshes/lidar_link.STL" />
      </geometry>
      <material
        name="">
        <color
          rgba="0.792156862745098 0.819607843137255 0.933333333333333 1" />
      </material>
    </visual>
    <collision>
      <origin
        xyz="0.08 0 0.1"
        rpy="0 0 3.14" />
      <geometry>
        <mesh
          filename="package://four_w_amr/meshes/lidar_link.STL" />
      </geometry>
    </collision>
  </link>
  <joint
    name="lidar_joint"
    type="fixed">
    <origin
      xyz="0.08 0 0.1"
      rpy="0 0 3.14" />
    <parent
      link="base_link" />
    <child
      link="lidar_link" />
    <axis
      xyz="0 0 0" />
  </joint>
  <link
    name="realsense_link">
    <inertial>
      <origin
        xyz="0 0 0"
        rpy="0 0 0" />
      <mass
        value="0" />
      <inertia
        ixx="0"
        ixy="0"
        ixz="0"
        iyy="0"
        iyz="0"
        izz="0" />
    </inertial>
    <visual>
      <origin
        xyz="0 0 0"
        rpy="0 0 0" />
      <geometry>
        <mesh
          filename="package://four_w_amr/meshes/realsense_link.STL" />
      </geometry>
      <material
        name="">
        <color
          rgba="1 1 1 1" />
      </material>
    </visual>
    <collision>
      <origin
        xyz="0 0 0"
        rpy="0 0 0" />
      <geometry>
        <mesh
          filename="package://four_w_amr/meshes/realsense_link.STL" />
      </geometry>
    </collision>
  </link>
  <joint
    name="realsense_joint"
    type="fixed">
    <origin
      xyz="0 0 0"
      rpy="0 0 0" />
    <parent
      link="base_link" />
    <child
      link="realsense_link" />
    <axis
      xyz="0 0 0" />
  </joint>
</robot>